
(venv) PS C:\americo\API\TaskGenie> deactivate
PS C:\americo\API\TaskGenie> venv\Scripts\activate    
(venv) PS C:\americo\API\TaskGenie> uvicorn main:app --reload
>> 
INFO:     Will watch for changes in these directories: ['C:\\americo\\API\\TaskGenie']
INFO:     Uvicorn running on http://127.0.0.1:8000 (Press CTRL+C to quit)
INFO:     Started reloader process [7500] using StatReload
C:\americo\API\TaskGenie\venv\Lib\site-packages\pydantic\_internal\_config.py:373: UserWarning: Valid config keys have changed in V2:
* 'orm_mode' has been renamed to 'from_attributes'
  warnings.warn(message, UserWarning)
INFO:     Started server process [6384]
INFO:     Waiting for application startup.
INFO:     Application startup complete.
INFO:     127.0.0.1:54347 - "GET / HTTP/1.1" 200 OK
INFO:     127.0.0.1:54348 - "GET /registro HTTP/1.1" 200 OK
WARNING:  StatReload detected changes in 'auth.py'. Reloading...
 INFO:     Shutting down
INFO:     Waiting for application shutdown.
INFO:     Application shutdown complete.
INFO:     Finished server process [6384]
C:\americo\API\TaskGenie\venv\Lib\site-packages\pydantic\_internal\_config.py:373: UserWarning: Valid config keys have changed in V2:
* 'orm_mode' has been renamed to 'from_attributes'
  warnings.warn(message, UserWarning)
INFO:     Started server process [8704]
INFO:     Waiting for application startup.
INFO:     Application startup complete.
INFO:     127.0.0.1:55000 - "POST /registro_form HTTP/1.1" 302 Found
INFO:     127.0.0.1:55000 - "GET /login HTTP/1.1" 200 OK
INFO:     127.0.0.1:55001 - "POST /login_form HTTP/1.1" 302 Found
INFO:     127.0.0.1:55001 - "GET /dashboard_admin HTTP/1.1" 200 OK
INFO:     127.0.0.1:55001 - "GET /admin/usuarios HTTP/1.1" 500 Internal Server Error
ERROR:    Exception in ASGI application
Traceback (most recent call last):
  File "C:\americo\API\TaskGenie\venv\Lib\site-packages\uvicorn\protocols\http\h11_impl.py", line 403, in run_asgi
    result = await app(  # type: ignore[func-returns-value]
             ^^^^^^^^^^^^^^^^^^^^^^^^^^^^^^^^^^^^^^^^^^^^^^
  File "C:\americo\API\TaskGenie\venv\Lib\site-packages\uvicorn\middleware\proxy_headers.py", line 60, in __call__
    return await self.app(scope, receive, send)
           ^^^^^^^^^^^^^^^^^^^^^^^^^^^^^^^^^^^^
  File "C:\americo\API\TaskGenie\venv\Lib\site-packages\fastapi\applications.py", line 1054, in __call__
    await super().__call__(scope, receive, send)
  File "C:\americo\API\TaskGenie\venv\Lib\site-packages\starlette\applications.py", line 112, in __call__
    await self.middleware_stack(scope, receive, send)
  File "C:\americo\API\TaskGenie\venv\Lib\site-packages\starlette\middleware\errors.py", line 187, in __call__
    raise exc
  File "C:\americo\API\TaskGenie\venv\Lib\site-packages\starlette\middleware\errors.py", line 165, in __call__
    await self.app(scope, receive, _send)
  File "C:\americo\API\TaskGenie\venv\Lib\site-packages\starlette\middleware\exceptions.py", line 62, in __call__
    await wrap_app_handling_exceptions(self.app, conn)(scope, receive, send)
  File "C:\americo\API\TaskGenie\venv\Lib\site-packages\starlette\_exception_handler.py", line 53, in wrapped_app
    raise exc
  File "C:\americo\API\TaskGenie\venv\Lib\site-packages\starlette\_exception_handler.py", line 42, in wrapped_app
    await app(scope, receive, sender)
  File "C:\americo\API\TaskGenie\venv\Lib\site-packages\starlette\routing.py", line 714, in __call__
    await self.middleware_stack(scope, receive, send)
  File "C:\americo\API\TaskGenie\venv\Lib\site-packages\starlette\routing.py", line 734, in app
    await route.handle(scope, receive, send)
  File "C:\americo\API\TaskGenie\venv\Lib\site-packages\starlette\routing.py", line 288, in handle
    await self.app(scope, receive, send)
  File "C:\americo\API\TaskGenie\venv\Lib\site-packages\starlette\routing.py", line 76, in app
    await wrap_app_handling_exceptions(app, request)(scope, receive, send)
  File "C:\americo\API\TaskGenie\venv\Lib\site-packages\starlette\_exception_handler.py", line 53, in wrapped_app
    raise exc
  File "C:\americo\API\TaskGenie\venv\Lib\site-packages\starlette\_exception_handler.py", line 42, in wrapped_app
    await app(scope, receive, sender)
  File "C:\americo\API\TaskGenie\venv\Lib\site-packages\starlette\routing.py", line 73, in app
    response = await f(request)
               ^^^^^^^^^^^^^^^^
  File "C:\americo\API\TaskGenie\venv\Lib\site-packages\fastapi\routing.py", line 327, in app
    content = await serialize_response(
              ^^^^^^^^^^^^^^^^^^^^^^^^^
  File "C:\americo\API\TaskGenie\venv\Lib\site-packages\fastapi\routing.py", line 176, in serialize_response
    raise ResponseValidationError(
fastapi.exceptions.ResponseValidationError: 1 validation errors:
  {'type': 'date_from_datetime_parsing', 'loc': ('response', 0, 'fecha_nacimiento'), 'msg': 'Input should be a valid date or datetime, invalid date separator, expected `-`', 'input': '1970/12/18', 'ctx': {'error': 'invalid date separator, expected `-`'}}

INFO:     127.0.0.1:55116 - "GET /admin/usuarios HTTP/1.1" 500 Internal Server Error
ERROR:    Exception in ASGI application
Traceback (most recent call last):
  File "C:\americo\API\TaskGenie\venv\Lib\site-packages\uvicorn\protocols\http\h11_impl.py", line 403, in run_asgi
    result = await app(  # type: ignore[func-returns-value]
             ^^^^^^^^^^^^^^^^^^^^^^^^^^^^^^^^^^^^^^^^^^^^^^
  File "C:\americo\API\TaskGenie\venv\Lib\site-packages\uvicorn\middleware\proxy_headers.py", line 60, in __call__
    return await self.app(scope, receive, send)
           ^^^^^^^^^^^^^^^^^^^^^^^^^^^^^^^^^^^^
  File "C:\americo\API\TaskGenie\venv\Lib\site-packages\fastapi\applications.py", line 1054, in __call__
    await super().__call__(scope, receive, send)
  File "C:\americo\API\TaskGenie\venv\Lib\site-packages\starlette\applications.py", line 112, in __call__
    await self.middleware_stack(scope, receive, send)
  File "C:\americo\API\TaskGenie\venv\Lib\site-packages\starlette\middleware\errors.py", line 187, in __call__
    raise exc
  File "C:\americo\API\TaskGenie\venv\Lib\site-packages\starlette\middleware\errors.py", line 165, in __call__
    await self.app(scope, receive, _send)
  File "C:\americo\API\TaskGenie\venv\Lib\site-packages\starlette\middleware\exceptions.py", line 62, in __call__
    await wrap_app_handling_exceptions(self.app, conn)(scope, receive, send)
  File "C:\americo\API\TaskGenie\venv\Lib\site-packages\starlette\_exception_handler.py", line 53, in wrapped_app
    raise exc
  File "C:\americo\API\TaskGenie\venv\Lib\site-packages\starlette\_exception_handler.py", line 42, in wrapped_app
    await app(scope, receive, sender)
  File "C:\americo\API\TaskGenie\venv\Lib\site-packages\starlette\routing.py", line 714, in __call__
    await self.middleware_stack(scope, receive, send)
  File "C:\americo\API\TaskGenie\venv\Lib\site-packages\starlette\routing.py", line 734, in app
    await route.handle(scope, receive, send)
  File "C:\americo\API\TaskGenie\venv\Lib\site-packages\starlette\routing.py", line 288, in handle
    await self.app(scope, receive, send)
  File "C:\americo\API\TaskGenie\venv\Lib\site-packages\starlette\routing.py", line 76, in app
    await wrap_app_handling_exceptions(app, request)(scope, receive, send)
  File "C:\americo\API\TaskGenie\venv\Lib\site-packages\starlette\_exception_handler.py", line 53, in wrapped_app
    raise exc
  File "C:\americo\API\TaskGenie\venv\Lib\site-packages\starlette\_exception_handler.py", line 42, in wrapped_app
    await app(scope, receive, sender)
  File "C:\americo\API\TaskGenie\venv\Lib\site-packages\starlette\routing.py", line 73, in app
    response = await f(request)
               ^^^^^^^^^^^^^^^^
  File "C:\americo\API\TaskGenie\venv\Lib\site-packages\fastapi\routing.py", line 327, in app
    content = await serialize_response(
              ^^^^^^^^^^^^^^^^^^^^^^^^^
  File "C:\americo\API\TaskGenie\venv\Lib\site-packages\fastapi\routing.py", line 176, in serialize_response
    raise ResponseValidationError(
fastapi.exceptions.ResponseValidationError: 1 validation errors:
  {'type': 'date_from_datetime_parsing', 'loc': ('response', 0, 'fecha_nacimiento'), 'msg': 'Input should be a valid date or datetime, invalid date separator, expected `-`', 'input': '1970/12/18', 'ctx': {'error': 'invalid date separator, expected `-`'}}





















