(venv) PS C:\americo\API\TaskGenie> deactivate
PS C:\americo\API\TaskGenie> venv\Scripts\activate    
(venv) PS C:\americo\API\TaskGenie> uvicorn main:app --reload
>> 
INFO:     Will watch for changes in these directories: ['C:\\americo\\API\\TaskGenie']
INFO:     Uvicorn running on http://127.0.0.1:8000 (Press CTRL+C to quit)
INFO:     Started reloader process [1876] using StatReload
INFO:     Started server process [6648]
INFO:     Waiting for application startup.
INFO:     Application startup complete.
INFO:     127.0.0.1:60310 - "GET / HTTP/1.1" 200 OK
INFO:     127.0.0.1:60311 - "POST /login_form HTTP/1.1" 302 Found
INFO:     127.0.0.1:60311 - "GET /dashboard_admin HTTP/1.1" 200 OK
INFO:     127.0.0.1:60311 - "GET /admin/usuarios HTTP/1.1" 500 Internal Server Error
ERROR:    Exception in ASGI application
Traceback (most recent call last):
  File "C:\americo\API\TaskGenie\venv\Lib\site-packages\uvicorn\protocols\http\h11_impl.py", line 403, in run_asgi
    result = await app(  # type: ignore[func-returns-value]
             ^^^^^^^^^^^^^^^^^^^^^^^^^^^^^^^^^^^^^^^^^^^^^^
  File "C:\americo\API\TaskGenie\venv\Lib\site-packages\uvicorn\middleware\proxy_headers.py", line 60, in __call__
    return await self.app(scope, receive, send)
           ^^^^^^^^^^^^^^^^^^^^^^^^^^^^^^^^^^^^
  File "C:\americo\API\TaskGenie\venv\Lib\site-packages\fastapi\applications.py", line 1054, in __call__
    await super().__call__(scope, receive, send)
  File "C:\americo\API\TaskGenie\venv\Lib\site-packages\starlette\applications.py", line 112, in __call__
    await self.middleware_stack(scope, receive, send)
  File "C:\americo\API\TaskGenie\venv\Lib\site-packages\starlette\middleware\errors.py", line 187, in __call__
    raise exc
  File "C:\americo\API\TaskGenie\venv\Lib\site-packages\starlette\middleware\errors.py", line 165, in __call__
    await self.app(scope, receive, _send)
  File "C:\americo\API\TaskGenie\venv\Lib\site-packages\starlette\middleware\exceptions.py", line 62, in __call__
    await wrap_app_handling_exceptions(self.app, conn)(scope, receive, send)
  File "C:\americo\API\TaskGenie\venv\Lib\site-packages\starlette\_exception_handler.py", line 53, in wrapped_app
    raise exc
  File "C:\americo\API\TaskGenie\venv\Lib\site-packages\starlette\_exception_handler.py", line 42, in wrapped_app
    await app(scope, receive, sender)
  File "C:\americo\API\TaskGenie\venv\Lib\site-packages\starlette\routing.py", line 714, in __call__
    await self.middleware_stack(scope, receive, send)
  File "C:\americo\API\TaskGenie\venv\Lib\site-packages\starlette\routing.py", line 734, in app
    await route.handle(scope, receive, send)
  File "C:\americo\API\TaskGenie\venv\Lib\site-packages\starlette\routing.py", line 288, in handle
    await self.app(scope, receive, send)
  File "C:\americo\API\TaskGenie\venv\Lib\site-packages\starlette\routing.py", line 76, in app
    await wrap_app_handling_exceptions(app, request)(scope, receive, send)
  File "C:\americo\API\TaskGenie\venv\Lib\site-packages\starlette\_exception_handler.py", line 53, in wrapped_app
    raise exc
  File "C:\americo\API\TaskGenie\venv\Lib\site-packages\starlette\_exception_handler.py", line 42, in wrapped_app
    await app(scope, receive, sender)
  File "C:\americo\API\TaskGenie\venv\Lib\site-packages\starlette\routing.py", line 73, in app
    response = await f(request)
               ^^^^^^^^^^^^^^^^
  File "C:\americo\API\TaskGenie\venv\Lib\site-packages\fastapi\routing.py", line 327, in app
    content = await serialize_response(
              ^^^^^^^^^^^^^^^^^^^^^^^^^
  File "C:\americo\API\TaskGenie\venv\Lib\site-packages\fastapi\routing.py", line 176, in serialize_response
    raise ResponseValidationError(
fastapi.exceptions.ResponseValidationError: 1 validation errors:
  {'type': 'date_from_datetime_parsing', 'loc': ('response', 0, 'fecha_nacimiento'), 'msg': 'Input should be a valid date or datetime, invalid date separator, expected `-`', 'input': '1970/12/18', 'ctx': {'error': 'invalid date separator, expected `-`'}}
























