(venv) PS C:\americo\API\TaskGenie> uvicorn main:app --reload
>> 
INFO:     Will watch for changes in these directories: ['C:\\americo\\API\\TaskGenie']
INFO:     Uvicorn running on http://127.0.0.1:8000 (Press CTRL+C to quit)
INFO:     Started reloader process [47336] using StatReload
INFO:     Started server process [40580]
INFO:     Waiting for application startup.
INFO:     Application startup complete.
INFO:     127.0.0.1:58230 - "GET / HTTP/1.1" 200 OK
INFO:     127.0.0.1:58230 - "GET /registro HTTP/1.1" 200 OK
INFO:     127.0.0.1:58230 - "POST /registro_form HTTP/1.1" 500 Internal Server Error
ERROR:    Exception in ASGI application
Traceback (most recent call last):
  File "C:\americo\API\TaskGenie\venv\Lib\site-packages\sqlalchemy\engine\base.py", line 1963, in _exec_single_context
    self.dialect.do_execute(
  File "C:\americo\API\TaskGenie\venv\Lib\site-packages\sqlalchemy\engine\default.py", line 943, in do_execute
    cursor.execute(statement, parameters)
sqlite3.IntegrityError: UNIQUE constraint failed: usuarios.email

The above exception was the direct cause of the following exception:

Traceback (most recent call last):
  File "C:\americo\API\TaskGenie\venv\Lib\site-packages\uvicorn\protocols\http\h11_impl.py", line 403, in run_asgi
    result = await app(  # type: ignore[func-returns-value]
             ^^^^^^^^^^^^^^^^^^^^^^^^^^^^^^^^^^^^^^^^^^^^^^
  File "C:\americo\API\TaskGenie\venv\Lib\site-packages\uvicorn\middleware\proxy_headers.py", line 60, in __call__
    return await self.app(scope, receive, send)
           ^^^^^^^^^^^^^^^^^^^^^^^^^^^^^^^^^^^^
  File "C:\americo\API\TaskGenie\venv\Lib\site-packages\fastapi\applications.py", line 1054, in __call__
    await super().__call__(scope, receive, send)
  File "C:\americo\API\TaskGenie\venv\Lib\site-packages\starlette\applications.py", line 112, in __call__
    await self.middleware_stack(scope, receive, send)
  File "C:\americo\API\TaskGenie\venv\Lib\site-packages\starlette\middleware\errors.py", line 187, in __call__
    raise exc
  File "C:\americo\API\TaskGenie\venv\Lib\site-packages\starlette\middleware\errors.py", line 165, in __call__
    await self.app(scope, receive, _send)
  File "C:\americo\API\TaskGenie\venv\Lib\site-packages\starlette\middleware\exceptions.py", line 62, in __call__
    await wrap_app_handling_exceptions(self.app, conn)(scope, receive, send)
  File "C:\americo\API\TaskGenie\venv\Lib\site-packages\starlette\_exception_handler.py", line 53, in wrapped_app
    raise exc
  File "C:\americo\API\TaskGenie\venv\Lib\site-packages\starlette\_exception_handler.py", line 42, in wrapped_app
    await app(scope, receive, sender)
  File "C:\americo\API\TaskGenie\venv\Lib\site-packages\starlette\routing.py", line 714, in __call__
    await self.middleware_stack(scope, receive, send)
  File "C:\americo\API\TaskGenie\venv\Lib\site-packages\starlette\routing.py", line 734, in app
    await route.handle(scope, receive, send)
  File "C:\americo\API\TaskGenie\venv\Lib\site-packages\starlette\routing.py", line 288, in handle
    await self.app(scope, receive, send)
  File "C:\americo\API\TaskGenie\venv\Lib\site-packages\starlette\routing.py", line 76, in app
    await wrap_app_handling_exceptions(app, request)(scope, receive, send)
  File "C:\americo\API\TaskGenie\venv\Lib\site-packages\starlette\_exception_handler.py", line 53, in wrapped_app
    raise exc
  File "C:\americo\API\TaskGenie\venv\Lib\site-packages\starlette\_exception_handler.py", line 42, in wrapped_app
    await app(scope, receive, sender)
  File "C:\americo\API\TaskGenie\venv\Lib\site-packages\starlette\routing.py", line 73, in app
    response = await f(request)
               ^^^^^^^^^^^^^^^^
  File "C:\americo\API\TaskGenie\venv\Lib\site-packages\fastapi\routing.py", line 301, in app
    raw_response = await run_endpoint_function(
                   ^^^^^^^^^^^^^^^^^^^^^^^^^^^^
  File "C:\americo\API\TaskGenie\venv\Lib\site-packages\fastapi\routing.py", line 214, in run_endpoint_function
    return await run_in_threadpool(dependant.call, **values)
           ^^^^^^^^^^^^^^^^^^^^^^^^^^^^^^^^^^^^^^^^^^^^^^^^^
  File "C:\americo\API\TaskGenie\venv\Lib\site-packages\starlette\concurrency.py", line 37, in run_in_threadpool
    return await anyio.to_thread.run_sync(func)
           ^^^^^^^^^^^^^^^^^^^^^^^^^^^^^^^^^^^^
  File "C:\americo\API\TaskGenie\venv\Lib\site-packages\anyio\to_thread.py", line 56, in run_sync
    return await get_async_backend().run_sync_in_worker_thread(
           ^^^^^^^^^^^^^^^^^^^^^^^^^^^^^^^^^^^^^^^^^^^^^^^^^^^^
  File "C:\americo\API\TaskGenie\venv\Lib\site-packages\anyio\_backends\_asyncio.py", line 2470, in run_sync_in_worker_thread
    return await future
           ^^^^^^^^^^^^
  File "C:\americo\API\TaskGenie\venv\Lib\site-packages\anyio\_backends\_asyncio.py", line 967, in run
    result = context.run(func, *args)
             ^^^^^^^^^^^^^^^^^^^^^^^^
  File "C:\americo\API\TaskGenie\auth.py", line 49, in registrar_usuario_form
    db.commit()
  File "C:\americo\API\TaskGenie\venv\Lib\site-packages\sqlalchemy\orm\session.py", line 2032, in commit
    trans.commit(_to_root=True)
  File "<string>", line 2, in commit
  File "C:\americo\API\TaskGenie\venv\Lib\site-packages\sqlalchemy\orm\state_changes.py", line 139, in _go
    ret_value = fn(self, *arg, **kw)
                ^^^^^^^^^^^^^^^^^^^^
  File "C:\americo\API\TaskGenie\venv\Lib\site-packages\sqlalchemy\orm\session.py", line 1313, in commit
    self._prepare_impl()
  File "<string>", line 2, in _prepare_impl
  File "C:\americo\API\TaskGenie\venv\Lib\site-packages\sqlalchemy\orm\state_changes.py", line 139, in _go
    ret_value = fn(self, *arg, **kw)
                ^^^^^^^^^^^^^^^^^^^^
  File "C:\americo\API\TaskGenie\venv\Lib\site-packages\sqlalchemy\orm\session.py", line 1288, in _prepare_impl
    self.session.flush()
  File "C:\americo\API\TaskGenie\venv\Lib\site-packages\sqlalchemy\orm\session.py", line 4345, in flush
    self._flush(objects)
  File "C:\americo\API\TaskGenie\venv\Lib\site-packages\sqlalchemy\orm\session.py", line 4480, in _flush
    with util.safe_reraise():
         ^^^^^^^^^^^^^^^^^^^
  File "C:\americo\API\TaskGenie\venv\Lib\site-packages\sqlalchemy\util\langhelpers.py", line 224, in __exit__
    raise exc_value.with_traceback(exc_tb)
  File "C:\americo\API\TaskGenie\venv\Lib\site-packages\sqlalchemy\orm\session.py", line 4441, in _flush
    flush_context.execute()
  File "C:\americo\API\TaskGenie\venv\Lib\site-packages\sqlalchemy\orm\unitofwork.py", line 466, in execute
    rec.execute(self)
  File "C:\americo\API\TaskGenie\venv\Lib\site-packages\sqlalchemy\orm\unitofwork.py", line 642, in execute
    util.preloaded.orm_persistence.save_obj(
  File "C:\americo\API\TaskGenie\venv\Lib\site-packages\sqlalchemy\orm\persistence.py", line 93, in save_obj
    _emit_insert_statements(
  File "C:\americo\API\TaskGenie\venv\Lib\site-packages\sqlalchemy\orm\persistence.py", line 1233, in _emit_insert_statements
    result = connection.execute(
             ^^^^^^^^^^^^^^^^^^^
  File "C:\americo\API\TaskGenie\venv\Lib\site-packages\sqlalchemy\engine\base.py", line 1415, in execute
    return meth(
           ^^^^^
  File "C:\americo\API\TaskGenie\venv\Lib\site-packages\sqlalchemy\sql\elements.py", line 523, in _execute_on_connection
    return connection._execute_clauseelement(
           ^^^^^^^^^^^^^^^^^^^^^^^^^^^^^^^^^^
  File "C:\americo\API\TaskGenie\venv\Lib\site-packages\sqlalchemy\engine\base.py", line 1637, in _execute_clauseelement
    ret = self._execute_context(
          ^^^^^^^^^^^^^^^^^^^^^^
  File "C:\americo\API\TaskGenie\venv\Lib\site-packages\sqlalchemy\engine\base.py", line 1842, in _execute_context
    return self._exec_single_context(
           ^^^^^^^^^^^^^^^^^^^^^^^^^^
  File "C:\americo\API\TaskGenie\venv\Lib\site-packages\sqlalchemy\engine\base.py", line 1982, in _exec_single_context
    self._handle_dbapi_exception(
  File "C:\americo\API\TaskGenie\venv\Lib\site-packages\sqlalchemy\engine\base.py", line 2351, in _handle_dbapi_exception
    raise sqlalchemy_exception.with_traceback(exc_info[2]) from e
  File "C:\americo\API\TaskGenie\venv\Lib\site-packages\sqlalchemy\engine\base.py", line 1963, in _exec_single_context
    self.dialect.do_execute(
             ^^^^^^^^^^^^^^^^^^^
  File "C:\americo\API\TaskGenie\venv\Lib\site-packages\sqlalchemy\engine\base.py", line 1415, in execute
    return meth(
           ^^^^^
  File "C:\americo\API\TaskGenie\venv\Lib\site-packages\sqlalchemy\sql\elements.py", line 523, in _execute_on_connection
    return connection._execute_clauseelement(
           ^^^^^^^^^^^^^^^^^^^^^^^^^^^^^^^^^^
  File "C:\americo\API\TaskGenie\venv\Lib\site-packages\sqlalchemy\engine\base.py", line 1637, in _execute_clauseelement
    ret = self._execute_context(
          ^^^^^^^^^^^^^^^^^^^^^^
  File "C:\americo\API\TaskGenie\venv\Lib\site-packages\sqlalchemy\engine\base.py", line 1842, in _execute_context
    return self._exec_single_context(
           ^^^^^^^^^^^^^^^^^^^^^^^^^^
  File "C:\americo\API\TaskGenie\venv\Lib\site-packages\sqlalchemy\engine\base.py", line 1982, in _exec_single_context
    self._handle_dbapi_exception(
  File "C:\americo\API\TaskGenie\venv\Lib\site-packages\sqlalchemy\engine\base.py", line 2351, in _handle_dbapi_exception
    raise sqlalchemy_exception.with_traceback(exc_info[2]) from e
  File "C:\americo\API\TaskGenie\venv\Lib\site-packages\sqlalchemy\engine\base.py", line 1963, in _exec_single_context
    self.dialect.do_execute(
  File "C:\americo\API\TaskGenie\venv\Lib\site-packages\sqlalchemy\engine\base.py", line 1415, in execute
    return meth(
           ^^^^^
  File "C:\americo\API\TaskGenie\venv\Lib\site-packages\sqlalchemy\sql\elements.py", line 523, in _execute_on_connection
    return connection._execute_clauseelement(
           ^^^^^^^^^^^^^^^^^^^^^^^^^^^^^^^^^^
  File "C:\americo\API\TaskGenie\venv\Lib\site-packages\sqlalchemy\engine\base.py", line 1637, in _execute_clauseelement
    ret = self._execute_context(
          ^^^^^^^^^^^^^^^^^^^^^^
  File "C:\americo\API\TaskGenie\venv\Lib\site-packages\sqlalchemy\engine\base.py", line 1842, in _execute_context
    return self._exec_single_context(
           ^^^^^^^^^^^^^^^^^^^^^^^^^^
  File "C:\americo\API\TaskGenie\venv\Lib\site-packages\sqlalchemy\engine\base.py", line 1982, in _exec_single_context
    self._handle_dbapi_exception(
  File "C:\americo\API\TaskGenie\venv\Lib\site-packages\sqlalchemy\engine\base.py", line 2351, in _handle_dbapi_exception
    raise sqlalchemy_exception.with_traceback(exc_info[2]) from e
  File "C:\americo\API\TaskGenie\venv\Lib\site-packages\sqlalchemy\engine\base.py", line 1963, in _exec_single_context
    self.dialect.do_execute(
  File "C:\americo\API\TaskGenie\venv\Lib\site-packages\sqlalchemy\sql\elements.py", line 523, in _execute_on_connection
    return connection._execute_clauseelement(
           ^^^^^^^^^^^^^^^^^^^^^^^^^^^^^^^^^^
  File "C:\americo\API\TaskGenie\venv\Lib\site-packages\sqlalchemy\engine\base.py", line 1637, in _execute_clauseelement
    ret = self._execute_context(
          ^^^^^^^^^^^^^^^^^^^^^^
  File "C:\americo\API\TaskGenie\venv\Lib\site-packages\sqlalchemy\engine\base.py", line 1842, in _execute_context
    return self._exec_single_context(
           ^^^^^^^^^^^^^^^^^^^^^^^^^^
  File "C:\americo\API\TaskGenie\venv\Lib\site-packages\sqlalchemy\engine\base.py", line 1982, in _exec_single_context
    self._handle_dbapi_exception(
  File "C:\americo\API\TaskGenie\venv\Lib\site-packages\sqlalchemy\engine\base.py", line 2351, in _handle_dbapi_exception
    raise sqlalchemy_exception.with_traceback(exc_info[2]) from e
  File "C:\americo\API\TaskGenie\venv\Lib\site-packages\sqlalchemy\engine\base.py", line 1963, in _exec_single_context
    self.dialect.do_execute(
           ^^^^^^^^^^^^^^^^^^^^^^^^^^^^^^^^^^
  File "C:\americo\API\TaskGenie\venv\Lib\site-packages\sqlalchemy\engine\base.py", line 1637, in _execute_clauseelement
    ret = self._execute_context(
          ^^^^^^^^^^^^^^^^^^^^^^
  File "C:\americo\API\TaskGenie\venv\Lib\site-packages\sqlalchemy\engine\base.py", line 1842, in _execute_context
    return self._exec_single_context(
           ^^^^^^^^^^^^^^^^^^^^^^^^^^
  File "C:\americo\API\TaskGenie\venv\Lib\site-packages\sqlalchemy\engine\base.py", line 1982, in _exec_single_context
    self._handle_dbapi_exception(
  File "C:\americo\API\TaskGenie\venv\Lib\site-packages\sqlalchemy\engine\base.py", line 2351, in _handle_dbapi_exception
    raise sqlalchemy_exception.with_traceback(exc_info[2]) from e
  File "C:\americo\API\TaskGenie\venv\Lib\site-packages\sqlalchemy\engine\base.py", line 1963, in _exec_single_context
    self.dialect.do_execute(
          ^^^^^^^^^^^^^^^^^^^^^^
  File "C:\americo\API\TaskGenie\venv\Lib\site-packages\sqlalchemy\engine\base.py", line 1842, in _execute_context
    return self._exec_single_context(
           ^^^^^^^^^^^^^^^^^^^^^^^^^^
  File "C:\americo\API\TaskGenie\venv\Lib\site-packages\sqlalchemy\engine\base.py", line 1982, in _exec_single_context
    self._handle_dbapi_exception(
  File "C:\americo\API\TaskGenie\venv\Lib\site-packages\sqlalchemy\engine\base.py", line 2351, in _handle_dbapi_exception
    raise sqlalchemy_exception.with_traceback(exc_info[2]) from e
  File "C:\americo\API\TaskGenie\venv\Lib\site-packages\sqlalchemy\engine\base.py", line 1963, in _exec_single_context
    self.dialect.do_execute(
           ^^^^^^^^^^^^^^^^^^^^^^^^^^
  File "C:\americo\API\TaskGenie\venv\Lib\site-packages\sqlalchemy\engine\base.py", line 1982, in _exec_single_context
    self._handle_dbapi_exception(
  File "C:\americo\API\TaskGenie\venv\Lib\site-packages\sqlalchemy\engine\base.py", line 2351, in _handle_dbapi_exception
    raise sqlalchemy_exception.with_traceback(exc_info[2]) from e
  File "C:\americo\API\TaskGenie\venv\Lib\site-packages\sqlalchemy\engine\base.py", line 1963, in _exec_single_context
    self.dialect.do_execute(
  File "C:\americo\API\TaskGenie\venv\Lib\site-packages\sqlalchemy\engine\base.py", line 2351, in _handle_dbapi_exception
    raise sqlalchemy_exception.with_traceback(exc_info[2]) from e
  File "C:\americo\API\TaskGenie\venv\Lib\site-packages\sqlalchemy\engine\base.py", line 1963, in _exec_single_context
    self.dialect.do_execute(
    raise sqlalchemy_exception.with_traceback(exc_info[2]) from e
  File "C:\americo\API\TaskGenie\venv\Lib\site-packages\sqlalchemy\engine\base.py", line 1963, in _exec_single_context
    self.dialect.do_execute(
  File "C:\americo\API\TaskGenie\venv\Lib\site-packages\sqlalchemy\engine\base.py", line 1963, in _exec_single_context
    self.dialect.do_execute(
    self.dialect.do_execute(
  File "C:\americo\API\TaskGenie\venv\Lib\site-packages\sqlalchemy\engine\default.py", line 943, in do_execute
    cursor.execute(statement, parameters)
sqlalchemy.exc.IntegrityError: (sqlite3.IntegrityError) UNIQUE constraint failed: usuarios.email
[SQL: INSERT INTO usuarios (nombre, apellido, edad, fecha_nacimiento, email, clave) VALUES (?, ?, ?, ?, ?, ?)]
[parameters: ('Americo2', 'Carrillo', 55, '1970/12/18', 'amejosecar@gmail.com', 'asasdasd')]
(Background on this error at: https://sqlalche.me/e/20/gkpj)
INFO:     127.0.0.1:58231 - "GET /.well-known/appspecific/com.chrome.devtools.json HTTP/1.1" 404 Not Found